Traceback (most recent call last):
  File "/opt/miniconda3/envs/jupyter-book/lib/python3.7/site-packages/jupyter_cache/executors/utils.py", line 56, in single_nb_execution
    record_timing=False,
  File "/opt/miniconda3/envs/jupyter-book/lib/python3.7/site-packages/nbclient/client.py", line 1112, in execute
    return NotebookClient(nb=nb, resources=resources, km=km, **kwargs).execute()
  File "/opt/miniconda3/envs/jupyter-book/lib/python3.7/site-packages/nbclient/util.py", line 74, in wrapped
    return just_run(coro(*args, **kwargs))
  File "/opt/miniconda3/envs/jupyter-book/lib/python3.7/site-packages/nbclient/util.py", line 53, in just_run
    return loop.run_until_complete(coro)
  File "/opt/miniconda3/envs/jupyter-book/lib/python3.7/asyncio/base_events.py", line 587, in run_until_complete
    return future.result()
  File "/opt/miniconda3/envs/jupyter-book/lib/python3.7/site-packages/nbclient/client.py", line 554, in async_execute
    cell, index, execution_count=self.code_cells_executed + 1
  File "/opt/miniconda3/envs/jupyter-book/lib/python3.7/site-packages/nbclient/client.py", line 857, in async_execute_cell
    self._check_raise_for_error(cell, exec_reply)
  File "/opt/miniconda3/envs/jupyter-book/lib/python3.7/site-packages/nbclient/client.py", line 760, in _check_raise_for_error
    raise CellExecutionError.from_cell_and_msg(cell, exec_reply_content)
nbclient.exceptions.CellExecutionError: An error occurred while executing the following cell:
------------------
import regionmask
import geopandas as gpd

china_shp = gpd.read_file('../shp_file/simplied_china_country.shp',encoding='utf8')
china_mask_poly = regionmask.Regions(china_shp.geometry,names='china')

china_mask = china_mask_poly.mask(mon_air)
#china_mask= np.ma.masked_invalid(china_mask)
china_mask = xr.where(china_mask==0,1.0,china_mask)
china_mask.plot()
------------------

[0;31m---------------------------------------------------------------------------[0m
[0;31mModuleNotFoundError[0m                       Traceback (most recent call last)
[0;32m<ipython-input-15-a3bb9010a30c>[0m in [0;36m<module>[0;34m[0m
[0;32m----> 1[0;31m [0;32mimport[0m [0mregionmask[0m[0;34m[0m[0;34m[0m[0m
[0m[1;32m      2[0m [0;32mimport[0m [0mgeopandas[0m [0;32mas[0m [0mgpd[0m[0;34m[0m[0;34m[0m[0m
[1;32m      3[0m [0;34m[0m[0m
[1;32m      4[0m [0mchina_shp[0m [0;34m=[0m [0mgpd[0m[0;34m.[0m[0mread_file[0m[0;34m([0m[0;34m'../shp_file/simplied_china_country.shp'[0m[0;34m,[0m[0mencoding[0m[0;34m=[0m[0;34m'utf8'[0m[0;34m)[0m[0;34m[0m[0;34m[0m[0m
[1;32m      5[0m [0mchina_mask_poly[0m [0;34m=[0m [0mregionmask[0m[0;34m.[0m[0mRegions[0m[0;34m([0m[0mchina_shp[0m[0;34m.[0m[0mgeometry[0m[0;34m,[0m[0mnames[0m[0;34m=[0m[0;34m'china'[0m[0;34m)[0m[0;34m[0m[0;34m[0m[0m

[0;31mModuleNotFoundError[0m: No module named 'regionmask'
ModuleNotFoundError: No module named 'regionmask'

